Workbook

Sheet Resumen
A1: Comparativa de costos de infraestructura: AWS vs Azure
A2: Estimación con precios de lista públicos consultados el 22/10/2026. No sustituye a las calculadoras oficiales: verificar los datos en amarillo de la hoja Supuestos antes de citar.
A4: Concepto (USD por mes) | B4: AWS On-Demand | C4: AWS Reserva 1 año | D4: Azure On-Demand | E4: Azure Reserva 1 año
A5: Base de datos | B5: =AWS!C12 -> 8563.9 | C5: =AWS!D12 -> 4933.9 | D5: =Azure!C12 -> 9028.745 | E5: =Azure!D12 -> 5524.745
A6: Cómputo de la aplicación | B6: =AWS!C17 -> 2426.152 | C6: =AWS!D17 -> 1751.632 | D6: =Azure!C17 -> 2426.152 | E6: =Azure!D17 -> 1567.672
A7: Logs de auditoría a 5 años | B7: =AWS!C24 -> 402.0826 | C7: =AWS!D24 -> 402.0826 | D7: =Azure!C24 -> 392.92014 | E7: =Azure!D24 -> 392.92014
A8: Borde, balanceo y WAF | B8: =AWS!C31 -> 2009.5114 | C8: =AWS!D31 -> 2009.5114 | D8: =Azure!C32 -> 1983.9467 | E8: =Azure!D32 -> 1983.9467
A9: TOTAL MENSUAL BASE (sin DR ni caché) | B9: =SUM(B5:B8) -> 13401.646 | C9: =SUM(C5:C8) -> 9097.126 | D9: =SUM(D5:D8) -> 13831.764 | E9: =SUM(E5:E8) -> 9469.2839
A10: Réplica de DR entre regiones (opcional) | B10: =AWS!C36 -> 1370.155 | C10: =AWS!D36 -> 765.155 | D10: =Azure!C37 -> 1517.155 | E10: =Azure!D37 -> 933.155
A11: TOTAL MENSUAL BASE + DR (comparable entre nubes) | B11: =B9+B10 -> 14771.801 | C11: =C9+C10 -> 9862.281 | D11: =D9+D10 -> 15348.919 | E11: =E9+E10 -> 10402.439
A12: Caché de lectura (informativo; Azure pendiente) | B12: =AWS!C41 -> 599.33 | C12: =AWS!D41 -> 407.5444 | D12: Pendiente | E12: Pendiente
A14: Proyección a 3 años (OPEX sobre el total base + DR)
A15: OPEX año 1 (12 meses) | B15: =B11*12 -> 177261.61 | C15: =C11*12 -> 118347.37 | D15: =D11*12 -> 184187.03 | E15: =E11*12 -> 124829.27
A16: OPEX año 2 (con crecimiento) | B16: =B15*(1+Supuestos!$B$29) -> 194987.77 | C16: =C15*(1+Supuestos!$B$29) -> 130182.11 | D16: =D15*(1+Supuestos!$B$29) -> 202605.73 | E16: =E15*(1+Supuestos!$B$29) -> 137312.19
A17: OPEX año 3 (con crecimiento) | B17: =B16*(1+Supuestos!$B$29) -> 214486.55 | C17: =C16*(1+Supuestos!$B$29) -> 143200.32 | D17: =D16*(1+Supuestos!$B$29) -> 222866.3 | E17: =E16*(1+Supuestos!$B$29) -> 151043.41
A18: OPEX acumulado a 3 años | B18: =SUM(B15:B17) -> 586735.94 | C18: =SUM(C15:C17) -> 391729.8 | D18: =SUM(D15:D17) -> 609659.06 | E18: =SUM(E15:E17) -> 413184.87
A19: CAPEX inicial (ejemplo del enunciado) | B19: =Supuestos!$B$30 -> 15000 | C19: =Supuestos!$B$30 -> 15000 | D19: =Supuestos!$B$30 -> 15000 | E19: =Supuestos!$B$30 -> 15000
A20: COSTO TOTAL ACUMULADO A 3 AÑOS | B20: =B18+B19 -> 601735.94 | C20: =C18+C19 -> 406729.8 | D20: =D18+D19 -> 624659.06 | E20: =E18+E19 -> 428184.87
A22: Costo unitario (sobre el total mensual base + DR)
A23: USD por millón de solicitudes | B23: =B11/Supuestos!$B$9 -> 24.70614 | C23: =C11/Supuestos!$B$9 -> 16.494867 | D23: =D11/Supuestos!$B$9 -> 25.671381 | E23: =E11/Supuestos!$B$9 -> 17.398292
A24: USD por millón de boletos | B24: =B11/Supuestos!$B$12 -> 984.78673 | C24: =C11/Supuestos!$B$12 -> 657.4854 | D24: =D11/Supuestos!$B$12 -> 1023.2613 | E24: =E11/Supuestos!$B$12 -> 693.49592
A25: USD por boleto | B25: =B11/(Supuestos!$B$12*1000000) -> 0.00098478673 | C25: =C11/(Supuestos!$B$12*1000000) -> 0.0006574854 | D25: =D11/(Supuestos!$B$12*1000000) -> 0.0010232613 | E25: =E11/(Supuestos!$B$12*1000000) -> 0.00069349592
A27: Observaciones
A28: 1. La reserva de 1 año se aplica a la BD y a los nodos base; nodos de pico, logs y borde quedan a precio de lista.
A29: 2. AWS usa Graviton (r6g) en la BD. Azure no ofrece equivalente ARM en memoria optimizada. En x86, db.r6i.8xlarge y E32ds_v5 cuestan lo mismo en on-demand ($2,920 al mes, single-AZ).
A30: 3. El Standard Load Balancer de Azure (capa 4) no equivale al ALB de AWS (capa 7). En Azure, Front Door Premium cubre la capa 7 y el WAF.
A31: 4. Pendiente en Azure: precio del caché de lectura e IOPS adicionales. Los precios de almacenamiento y backup de Azure son provisionales (iguales a los de AWS).
A32: 5. Las celdas en amarillo (Supuesto, Pendiente, Terceros*) deben verificarse en las calculadoras oficiales antes de citarlas en el documento.
A33: 6. Con reserva de 3 años el costo baja más; no se calculó aquí.

Sheet Supuestos
A1: Supuestos y precios unitarios
A2: Azul = dato ingresado. Negro = fórmula. Fondo amarillo = dato a verificar en la calculadora oficial (Supuesto, Pendiente o Terceros*).
A3: Confianza: Oficial = página del proveedor; Terceros = agregador o blog que cita precios de lista; Terceros* = fuente débil o antigua; Derivado = calculado de otro precio; Supuesto = valor propio sin fuente.
A5: Concepto | B5: Valor | C5: Unidad | D5: Confianza | E5: Fuente o nota
A6: 1. Volúmenes y supuestos de dimensionamiento (provisionales: ajustar con la Etapa 1)
A7: Horas por mes | B7: 730 | C7: h/mes | D7: Convención | E7: Convención de las calculadoras de AWS y Azure (8,760 h dividido entre 12).
A8: GB por TB | B8: 1024 | C8: GB | D8: Convención | E8: Se usa 1 TB = 1,024 GB en los tramos de precio.
A9: Solicitudes mensuales al borde (CDN y WAF) | B9: 597.9 | C9: millones/mes | D9: Supuesto | E9: Configuración de prueba entregada al usuario. Reemplazar con el desglose de 50,000 TPS de la Etapa 1.
A10: Salida de datos a clientes | B10: 7.91 | C10: TB/mes | D10: Supuesto | E10: Configuración de prueba. Ajustar con el tamaño medio de respuesta de la Etapa 1.
A11: Tráfico del borde hacia el origen | B11: 2 | C11: TB/mes | D11: Supuesto | E11: Supuesto propio (fallos de caché y peticiones POST).
A12: Boletos vendidos por mes | B12: 15 | C12: millones/mes | D12: Enunciado | E12: Dato del enunciado del Proyecto 2.
A13: Almacenamiento de la BD (primaria y cada réplica) | B13: 497 | C13: GB | D13: Supuesto | E13: Datos vivos más particiones recientes de bitácoras. Ajustar con la tabla de almacenamiento de la Etapa 1.
A14: Réplicas de lectura | B14: 2 | C14: unidades | D14: Supuesto | E14: Configuración de prueba.
A15: Backup facturable (por encima del 100% gratuito del tamaño de la BD) | B15: 1024 | C15: GB | D15: Supuesto | E15: Ambas nubes incluyen backup gratis hasta el 100% del almacenamiento aprovisionado (usage.ai, nops.io).
A16: IOPS adicionales provisionadas en AWS | B16: 9000 | C16: IOPS | D16: Supuesto | E16: Objetivo de 12,000 menos 3,000 de base gp3. Podría ser 0 si el volumen de 1 TB ya incluye más IOPS base: verificar.
A17: Nodos Kubernetes base (24/7) | B17: 4 | C17: unidades | D17: Supuesto | E17: Configuración de prueba.
A18: Nodos Kubernetes adicionales en pico | B18: 4 | C18: unidades | D18: Supuesto | E18: Configuración de prueba.
... A30: CAPEX inicial | B30: 15000 | C30: USD | D30: Enunciado | E30: Ejemplo del enunciado ($15,000). Reemplazar con el CAPEX propio.
A31: 2. Precios unitarios de AWS (us-east-1, USD, consultados el 22/10/2026)
A32: RDS PostgreSQL db.r6g.8xlarge, single-AZ, on-demand | B32: 2626 | C32: USD/mes | D32: Terceros | E32: bytebase.com/dbcost (derivado de la lista de precios de AWS). El precio de db.r6g.16xlarge ($5,252) es exactamente el doble, lo que confirma que es single-AZ.
A33: RDS PostgreSQL db.r6g.8xlarge, single-AZ, reserva 1 año | B33: 1416 | C33: USD/mes | D33: Terceros* | E33: Tarifa efectiva mensual según el agregador; el descuento (46%) sugiere pago total adelantado. Sin pago inicial sería mayor.
A34: db.r6g.4xlarge, single-AZ, on-demand | B34: =$B$32/2 -> 1313 | C34: USD/mes | D34: Derivado | E34: Mitad del 8xlarge (los precios escalan de forma lineal dentro de la familia).
A35: db.r6g.4xlarge, single-AZ, reserva 1 año | B35: =$B$33/2 -> 708 | C35: USD/mes | D35: Derivado | E35: Mitad del 8xlarge.
A36: Factor Multi-AZ (instancia y almacenamiento) | B36: 2 | C36: x | D36: Terceros | E36: usage.ai, swyftstack.com y bytebase.com coinciden: Multi-AZ duplica instancia y almacenamiento.
A37: Almacenamiento gp3 (single-AZ) | B37: 0.115 | C37: USD/GB-mes | D37: Terceros | E37: usage.ai (jun 2026), swyftstack.com y bytebase.com. Una fuente antigua (rapydo.io) cita $0.08; se descartó.
A38: IOPS provisionadas sobre la base | B38: 0.02 | C38: USD/IOPS-mes | D38: Terceros | E38: usage.ai.
A39: Backup sobre el 100% gratuito | B39: 0.095 | C39: USD/GB-mes | D39: Terceros | E39: usage.ai, tigerdata.com y bytebase.com.
A40: EC2 m6i.4xlarge on-demand (Linux) | B40: 0.768 | C40: USD/h | D40: Terceros | E40: calculator.holori.com y devzero.io.
A41: EC2 m6i.4xlarge reserva 1 año sin pago inicial | B41: 0.537 | C41: USD/h | D41: Terceros | E41: devzero.io (Reserved 1Y).
A42: Amazon EKS, plano de control | B42: 0.1 | C42: USD/h | D42: Oficial | E42: Blog oficial de AWS sobre precios de EKS.
A43: S3 Standard (primeros 50 TB) | B43: 0.023 | C43: USD/GB-mes | D43: Terceros | E43: devzero.io (cita la AWS Price List Bulk API).
A44: S3 Glacier Flexible Retrieval | B44: 0.0036 | C44: USD/GB-mes | D44: Terceros | E44: devzero.io y cloudchipr.com.
A45: S3 Standard, solicitudes PUT | B45: 0.005 | C45: USD/1,000 | D45: Terceros | E45: upstash.com.
A46: Transición de ciclo de vida a Glacier Flexible | B46: 0.03 | C46: USD/1,000 | D46: Terceros* | E46: upstash.com; la columna se infirió de la tabla. Verificar.
A47: Recuperación estándar desde Glacier Flexible | B47: 0.01 | C47: USD/GB | D47: Terceros | E47: upstash.com.
... A58: ElastiCache cache.r6g.2xlarge on-demand | B58: 0.821 | C58: USD/h | D58: Terceros | E58: calculator.holori.com.
A59: ElastiCache cache.r6g.xlarge on-demand | B59: =$B$58/2 -> 0.4105 | C59: USD/h | D59: Derivado | E59: Mitad del 2xlarge.
A60: Descuento de reserva 1 año en ElastiCache | B60: 0.32 | C60: % | D60: Terceros | E60: calculator.holori.com (Reserved 1yr sin pago inicial).
A61: 3. Precios unitarios de Azure (East US, USD, consultados el 22/10/2026)
A62: PostgreSQL Flexible Server E32ds_v5 (solo cómputo), on-demand | B62: 2920 | C62: USD/mes | D62: Terceros | E62: bytebase.com/dbcost (actualizado jul 2026). Almacenamiento, HA y backups se cobran aparte.
...

Sheet AWS
A1: Estimado mensual en AWS (us-east-1)
A2: Precios de lista, USD por mes, consultados el 22/10/2026. Configuración y volúmenes en la hoja Supuestos.
A4: Componente | B4: Cálculo | C4: Mensual On-Demand (USD) | D4: Mensual Reserva 1 año (USD) | E4: Confianza | F4: Nota
A5: Base de datos (Amazon RDS for PostgreSQL)
A6: RDS primaria Multi-AZ (db.r6g.8xlarge) | B6: Precio single-AZ x factor Multi-AZ | C6: =Supuestos!$B$32*Supuestos!$B$36 -> 5252 | D6: =Supuestos!$B$33*Supuestos!$B$36 -> 2832 | E6: Terceros | F6: Graviton (ARM). Con x86 (db.r6i.8xlarge) el on-demand single-AZ es $2,920, igual que Azure E32ds_v5.
A7: Réplicas de lectura (db.r6g.4xlarge) | B7: N réplicas x precio single-AZ | C7: =Supuestos!$B$14*Supuestos!$B$34 -> 2626 | D7: =Supuestos!$B$14*Supuestos!$B$35 -> 1416 | E7: Derivado | F7: Las réplicas de lectura son single-AZ por defecto.
A8: Almacenamiento gp3 de la primaria (Multi-AZ) | B8: GB x USD/GB x factor Multi-AZ | C8: =Supuestos!$B$13*Supuestos!$B$37*Supuestos!$B$36 -> 114.31 | D8: =C8 -> 114.31 | E8: Terceros
A9: Almacenamiento gp3 de las réplicas | B9: N réplicas x GB x USD/GB | C9: =Supuestos!$B$14*Supuestos!$B$13*Supuestos!$B$37 -> 114.31 | D9: =C9 -> 114.31 | E9: Terceros
A10: IOPS adicionales (primaria Multi-AZ) | B10: IOPS x USD/IOPS x factor Multi-AZ | C10: =Supuestos!$B$16*Supuestos!$B$38*Supuestos!$B$36 -> 360 | D10: =C10 -> 360 | E10: Supuesto | F10: Podría ser 0 si el volumen de 1 TB ya incluye 12,000 IOPS de base. Verificar.
A11: Backups sobre el 100% gratuito | B11: GB facturables x USD/GB | C11: =Supuestos!$B$15*Supuestos!$B$39 -> 97.28 | D11: =C11 -> 97.28 | E11: Terceros | F11: Retención de 35 días.
A12: Subtotal base de datos | C12: =SUM(C6:C11) -> 8563.9 | D12: =SUM(D6:D11) -> 4933.9
A13: Cómputo de la aplicación (Amazon EKS)
A14: EKS, plano de control | B14: USD/h x horas del mes | C14: =Supuestos!$B$42*Supuestos!$B$7 -> 73 | D14: =C14 -> 73 | E14: Oficial
A15: Nodos base m6i.4xlarge 24/7 | B15: Nodos x horas x USD/h | C15: =Supuestos!$B$17*Supuestos!$B$7*Supuestos!$B$40 -> 2242.56 | D15: =Supuestos!$B$17*Supuestos!$B$7*Supuestos!$B$41 -> 1568.04 | E15: Terceros | F15: La reserva aplica solo a los nodos base.
A16: Nodos de pico (on-demand) | B16: Nodos x horas de pico x USD/h | C16: =Supuestos!$B$18*Supuestos!$B$19*Supuestos!$B$40 -> 110.592 | D16: =C16 -> 110.592 | E16: Terceros
A17: Subtotal cómputo | C17: =SUM(C14:C16) -> 2426.152 | D17: =SUM(D14:D16) -> 1751.632
A18: Logs de auditoría a 5 años (Amazon S3 y S3 Glacier)
A19: S3 Standard (capa caliente) | B19: GB x USD/GB | C19: =Supuestos!$B$23*Supuestos!$B$43 -> 0.989 | D19: =C19 -> 0.989 | E19: Terceros
A20: S3 Glacier Flexible Retrieval (archivo) | B20: GB x USD/GB | C20: =Supuestos!$B$24*Supuestos!$B$44 -> 0.0936 | D20: =C20 -> 0.0936 | E20: Terceros
A21: Solicitudes PUT a S3 | B21: Millones x 1,000 x USD/1,000 | C21: =Supuestos!$B$25*1000*Supuestos!$B$45 -> 250 | D21: =C21 -> 250 | E21: Terceros
A22: Transiciones de ciclo de vida a Glacier | B22: Millones x 1,000 x USD/1,000 | C22: =Supuestos!$B$26*1000*Supuestos!$B$46 -> 150 | D22: =C22 -> 150 | E22: Terceros*
A23: Recuperación de datos para auditoría | B23: GB x USD/GB | C23: =Supuestos!$B$27*Supuestos!$B$47 -> 1 | D23: =C23 -> 1 | E23: Terceros | F23: No incluye solicitudes de restauración.
A24: Subtotal logs a 5 años | C24: =SUM(C19:C23) -> 402.0826 | D24: =SUM(D19:D23) -> 402.0826
A25: Borde, balanceo y WAF
A26: CloudFront, salida a internet | B26: Tramo 1 + tramo 2 | C26: =MIN(Supuestos!$B$10,Supuestos!$B$50)*Supuestos!$B$8*Supuestos!$B$48+MAX(0,Supuestos!$B$10-Supuestos!$B$50)*Supuestos!$B$8*Supuestos!$B$49 -> 688.4864 | D26: =C26 -> 688.4864 | E26: Terceros
A27: CloudFront, solicitudes HTTPS | B27: Millones x 100 x USD/10,000 | C27: =Supuestos!$B$9*100*Supuestos!$B$51 -> 597.9 | D27: =C27 -> 597.9 | E27: Terceros | F27: Millones de solicitudes dividido entre 10,000 es millones x 100.
A28: CloudFront, tráfico hacia el origen | B28: TB x GB/TB x USD/GB | C28: =Supuestos!$B$11*Supuestos!$B$8*Supuestos!$B$52 -> 40.96 | D28: =C28 -> 40.96 | E28: Terceros
A29: AWS WAF | B29: Web ACL + reglas + solicitudes | C29: =Supuestos!$B$53+Supuestos!$B$21*Supuestos!$B$54+Supuestos!$B$9*Supuestos!$B$55 -> 373.74 | D29: =C29 -> 373.74 | E29: Oficial | F29: CloudFront no cobra las solicitudes bloqueadas por WAF, pero WAF sí las evalúa.
A30: Application Load Balancer | B30: Horas fijas + LCU promedio | C30: =Supuestos!$B$56*Supuestos!$B$7+Supuestos!$B$20*Supuestos!$B$57*Supuestos!$B$7 -> 308.425 | D30: =C30 -> 308.425 | E30: Supuesto | F30: Depende del LCU promedio supuesto.
A31: Subtotal borde, balanceo y WAF | C31: =SUM(C26:C30) -> 2009.5114 | D31: =SUM(D26:D30) -> 2009.5114
A32: TOTAL MENSUAL BASE (sin DR ni caché) | C32: =C12+C17+C24+C31 -> 13401.646 | D32: =D12+D17+D24+D31 -> 9097.126
A34: Opcional: réplica de DR entre regiones (16 vCPU, us-west-2)
A35: Réplica entre regiones db.r6g.4xlarge | B35: Instancia single-AZ + almacenamiento | C35: =Supuestos!$B$34+Supuestos!$B$13*Supuestos!$B$37 -> 1370.155 | D35: =Supuestos!$B$35+Supuestos!$B$13*Supuestos!$B$37 -> 765.155 | E35: Derivado | F35: No incluye transferencia de datos entre regiones. Verificar.
A36: Subtotal DR multi-región | C36: =SUM(C35:C35) -> 1370.155 | D36: =SUM(D35:D35) -> 765.155
A37: TOTAL MENSUAL BASE + DR | C37: =C32+C36 -> 14771.801 | D37: =D32+D36 -> 9862.281
A39: Opcional: caché de lectura (Amazon ElastiCache for Redis)
A40: Nodos cache.r6g.xlarge | B40: Nodos x USD/h x horas | C40: =Supuestos!$B$22*Supuestos!$B$59*Supuestos!$B$7 -> 599.33 | D40: =Supuestos!$B$22*Supuestos!$B$59*Supuestos!$B$7*(1-Supuestos!$B$60) -> 407.5444 | E40: Derivado | F40: Derivado del precio del 2xlarge.
A41: Subtotal caché (informativo) | C41: =SUM(C40:C40) -> 599.33 | D41: =SUM(D40:D40) -> 407.5444

Sheet Azure
A1: Estimado mensual en Azure (East US)
A2: Precios de lista, USD por mes, consultados el 22/10/2026. Configuración y volúmenes en la hoja Supuestos.
A4: Componente | B4: Cálculo | C4: Mensual On-Demand (USD) | D4: Mensual Reserva 1 año (USD) | E4: Confianza | F4: Nota
A5: Base de datos (Azure Database for PostgreSQL Flexible Server)
A6: Primaria E32ds_v5 con HA zona-redundante | B6: Precio de cómputo x factor HA | C6: =Supuestos!$B$62*Supuestos!$B$66 -> 5840 | D6: =Supuestos!$B$63*Supuestos!$B$66 -> 3504 | E6: Terceros | F6: Intel x86; no hay equivalente ARM en memoria optimizada.
A7: Réplicas de lectura E16ds_v5 | B7: N réplicas x precio de cómputo | C7: =Supuestos!$B$14*Supuestos!$B$64 -> 2920 | D7: =Supuestos!$B$14*Supuestos!$B$65 -> 1752 | E7: Derivado
A8: Almacenamiento de la primaria | B8: GB x USD/GB | C8: =Supuestos!$B$13*Supuestos!$B$67 -> 57.155 | D8: =C8 -> 57.155 | E8: Supuesto | F8: Según nops.io, la HA no duplica el almacenamiento. Verificar en la calculadora.
A9: Almacenamiento de las réplicas | B9: N réplicas x GB x USD/GB | C9: =Supuestos!$B$14*Supuestos!$B$13*Supuestos!$B$67 -> 114.31 | D9: =C9 -> 114.31 | E9: Supuesto
A10: IOPS adicionales | B10: No incluido | C10: =0 -> 0 | D10: =C10 -> 0 | E10: Pendiente | F10: No se encontró el precio. Verificar cuántas IOPS trae el disco de 1 TB y si se necesitan más.
A11: Backups sobre el 100% gratuito | B11: GB facturables x USD/GB | C11: =Supuestos!$B$15*Supuestos!$B$68 -> 97.28 | D11: =C11 -> 97.28 | E11: Supuesto
A12: Subtotal base de datos | C12: =SUM(C6:C11) -> 9028.745 | D12: =SUM(D6:D11) -> 5524.745
A13: Cómputo de la aplicación (Azure Kubernetes Service)
A14: AKS, plano de control nivel Standard | B14: USD/h x horas del mes | C14: =Supuestos!$B$71*Supuestos!$B$7 -> 73 | D14: =C14 -> 73 | E14: Supuesto | F14: Valor de conocimiento previo; verificar.
A15: Nodos base D16s_v5 24/7 | B15: Nodos x horas x USD/h | C15: =Supuestos!$B$17*Supuestos!$B$7*Supuestos!$B$69 -> 2242.56 | D15: =Supuestos!$B$17*Supuestos!$B$7*Supuestos!$B$70 -> 1384.08 | E15: Terceros | F15: La reserva aplica solo a los nodos base.
A16: Nodos de pico (on-demand) | B16: Nodos x horas de pico x USD/h | C16: =Supuestos!$B$18*Supuestos!$B$19*Supuestos!$B$69 -> 110.592 | D16: =C16 -> 110.592 | E16: Terceros
A17: Subtotal cómputo | C17: =SUM(C14:C16) -> 2426.152 | D17: =SUM(D14:D16) -> 1567.672
A18: Logs de auditoría a 5 años (Azure Blob Storage Hot y Archive)
A19: Blob Hot LRS (capa caliente) | B19: GB x USD/GB | C19: =Supuestos!$B$23*Supuestos!$B$72 -> 0.8944 | D19: =C19 -> 0.8944 | E19: Terceros
A20: Blob Archive LRS (archivo) | B20: GB x USD/GB | C20: =Supuestos!$B$24*Supuestos!$B$73 -> 0.02574 | D20: =C20 -> 0.02574 | E20: Terceros
A21: Operaciones de escritura en Hot | B21: Millones x 100 x USD/10,000 | C21: =Supuestos!$B$25*100*Supuestos!$B$74 -> 325 | D21: =C21 -> 325 | E21: Terceros*
A22: Escrituras a Archive (transición) | B22: Millones x 100 x USD/10,000 | C22: =Supuestos!$B$26*100*Supuestos!$B$75 -> 65 | D22: =C22 -> 65 | E22: Terceros*
A23: Recuperación de datos para auditoría | B23: GB x USD/GB | C23: =Supuestos!$B$27*Supuestos!$B$76 -> 2 | D23: =C23 -> 2 | E23: Terceros* | F23: No incluye operaciones de lectura por rehidratación.
A24: Subtotal logs a 5 años | C24: =SUM(C19:C23) -> 392.92014 | D24: =SUM(D19:D23) -> 392.92014
A25: Borde, balanceo y WAF
A26: Front Door Premium, cuota base | B26: Cuota fija mensual | C26: =Supuestos!$B$77 -> 330 | D26: =C26 -> 330 | E26: Oficial
A27: Front Door, solicitudes | B27: Millones x 100 x USD/10,000 | C27: =Supuestos!$B$9*100*Supuestos!$B$78 -> 896.85 | D27: =C27 -> 896.85 | E27: Terceros* | F27: Se aplica la tarifa de las primeras 250 millones a todo el volumen (conservador).
A28: Front Door, salida zona 1 | B28: Tramo 1 + tramo 2 | C28: =MIN(Supuestos!$B$10,Supuestos!$B$81)*Supuestos!$B$8*Supuestos!$B$79+MAX(0,Supuestos!$B$10-Supuestos!$B$81)*Supuestos!$B$8*Supuestos!$B$80 -> 672.28672 | D28: =C28 -> 672.28672 | E28: Terceros
A29: Front Door, borde hacia el origen | B29: TB x GB/TB x USD/GB | C29: =Supuestos!$B$11*Supuestos!$B$8*Supuestos!$B$82 -> 40.96 | D29: =C29 -> 40.96 | E29: Terceros
A30: WAF (incluido en Premium) | B30: Sin cargo adicional | C30: =0 -> 0 | D30: =C30 -> 0 | E30: Oficial | F30: Microsoft Learn (comparación de precios CDN y Front Door): Premium incluye reglas administradas y personalizadas.
A31: Standard Load Balancer | B31: Horas fijas + GB procesados | C31: =Supuestos!$B$83*Supuestos!$B$7+Supuestos!$B$28*Supuestos!$B$84 -> 43.85 | D31: =C31 -> 43.85 | E31: Terceros* | F31: Es de capa 4: no equivale a un ALB (capa 7). En Azure la capa 7 la cubre Front Door.
A32: Subtotal borde, balanceo y WAF | C32: =SUM(C26:C31) -> 1983.9467 | D32: =SUM(D26:D31) -> 1983.9467
A33: TOTAL MENSUAL BASE (sin DR ni caché) | C33: =C12+C17+C24+C32 -> 13831.764 | D33: =D12+D17+D24+D32 -> 9469.2839
A35: Opcional: réplica de DR entre regiones (16 vCPU, West US 2)
A36: Réplica entre regiones E16ds_v5 | B36: Cómputo + almacenamiento | C36: =Supuestos!$B$64+Supuestos!$B$13*Supuestos!$B$67 -> 1517.155 | D36: =Supuestos!$B$65+Supuestos!$B$13*Supuestos!$B$67 -> 933.155 | E36: Derivado | F36: No incluye transferencia de datos entre regiones. Verificar.
A37: Subtotal DR multi-región | C37: =SUM(C36:C36) -> 1517.155 | D37: =SUM(D36:D36) -> 933.155
A38: TOTAL MENSUAL BASE + DR | C38: =C33+C37 -> 15348.919 | D38: =D33+D37 -> 10402.439
A40: Opcional: caché de lectura (Azure Managed Redis o Azure Cache for Redis)
A41: PENDIENTE: no se encontró un precio utilizable | B41: Obtener de la calculadora oficial | C41: =0 -> 0 | D41: =C41 -> 0 | E41: Pendiente | F41: Elegir un tamaño equivalente a 2 nodos de unos 26 GB y agregarlo a mano.
A42: Subtotal caché (informativo) | C42: =SUM(C41:C41) -> 0 | D42: =SUM(D41:D41) -> 0

Sheet Fuentes
A1: Nube | B1: Se usó para | C1: URL | D1: Tipo | E1: Consultado
A2: AWS | B2: Calculadora oficial (verificar aquí) | C2: https://calculator.aws/ | D2: Oficial
A3: AWS | B3: Estructura de precios RDS PostgreSQL | C3: https://aws.amazon.com/rds/postgresql/pricing/ | D3: Oficial | E3: 2026-10-22
A4: AWS | B4: RDS db.r6g.8xlarge | C4: https://www.bytebase.com/dbcost/rds/instance/db.r6g.8xlarge/ | D4: Terceros | E4: 2026-10-22
A5: AWS | B5: RDS db.r6g.16xlarge (verificación del factor) | C5: https://www.bytebase.com/dbcost/rds/instance/db.r6g.16xlarge/ | D5: Terceros | E5: 2026-10-22
A6: AWS | B6: RDS db.r6i.8xlarge (variante x86) | C6: https://www.bytebase.com/dbcost/rds/instance/db.r6i.8xlarge/ | D6: Terceros | E6: 2026-10-22
A7: AWS | B7: RDS: gp3, backup, IOPS, factor Multi-AZ | C7: https://www.usage.ai/blogs/aws/reserved-instances/rds/pricing-calculator/ | D7: Terceros | E7: 2026-10-22
A8: AWS | B8: RDS: factor Multi-AZ y backup | C8: https://swyftstack.com/blog/aws-rds-pricing-explained | D8: Terceros | E8: 2026-10-22
A9: AWS | B9: EC2 m6i.4xlarge | C9: https://calculator.holori.com/aws/ec2/m6i.4xlarge | D9: Terceros | E9: 2026-10-22
A10: AWS | B10: EC2 m6i.4xlarge reservado | C10: https://www.devzero.io/instances/aws/m6i.4xlarge | D10: Terceros | E10: 2026-10-22
A11: AWS | B11: EKS, plano de control | C11: https://aws.amazon.com/blogs/containers/amazon-eks-extended-support-for-kubernetes-versions-pricing/ | D11: Oficial | E11: 2026-10-22
A12: AWS | B12: S3 Standard y Glacier | C12: https://www.devzero.io/blog/aws-s3-pricing | D12: Terceros | E12: 2026-10-22
A13: AWS | B13: S3: solicitudes PUT y recuperación | C13: https://upstash.com/blog/aws-s3-pricing-explained-2026 | D13: Terceros | E13: 2026-10-22
A14: AWS | B14: CloudFront: transferencia y solicitudes | C14: https://perfsys.com/blog/cloudfront-pricing-guide/ | D14: Terceros | E14: 2026-10-22
... A19: AWS | B19: ElastiCache cache.r6g.2xlarge | C19: https://calculator.holori.com/aws/elasticache/cache.r6g.2xlarge | D19: Terceros | E19: 2026-10-22
A20: Azure | B20: Calculadora oficial (verificar aquí) | C20: https://azure.microsoft.com/pricing/calculator/ | D20: Oficial
A21: Azure | B21: API oficial de precios (para verificar) | C21: https://learn.microsoft.com/en-us/rest/api/cost-management/retail-prices/azure-retail-prices | D21: Oficial | E21: 2026-10-22
A22: Azure | B22: PostgreSQL Flexible Server E32ds_v5 | C22: https://www.bytebase.com/dbcost/azure-flexible/instance/E32ds_v5/ | D22: Terceros | E22: 2026-10-22
A23: Azure | B23: PostgreSQL Flexible Server: comparación de 32 vCPU | C23: https://www.bytebase.com/dbcost/azure-flexible/compare/32-vcpu/ | D23: Terceros | E23: 2026-10-22
A24: Azure | B24: PostgreSQL: HA, backups, IOPS | C24: https://www.nops.io/blog/azure-database-postgresql-cost-optimization/ | D24: Terceros | E24: 2026-10-22
A25: Azure | B25: VM Standard_D16s_v5 | C25: https://calculator.holori.com/azure/vm/standard-d16s-v5/eastus | D25: Terceros | E25: 2026-10-22
A26: Azure | B26: VM Standard_D16s_v5 reservada | C26: https://www.devzero.io/instances/azure/Standard_D16s_v5 | D26: Terceros | E26: 2026-10-22
A27: Azure | B27: Front Door: cuotas base | C27: https://learn.microsoft.com/en-us/azure/frontdoor/understanding-pricing | D27: Oficial | E27: 2026-10-22
A28: Azure | B28: Front Door: WAF incluido en Premium | C28: https://learn.microsoft.com/en-us/azure/frontdoor/compare-cdn-front-door-price | D28: Oficial | E28: 2026-10-22
A29: Azure | B29: Front Door: tarifas por GB y solicitudes | C29: https://us.fitgap.com/products/azure-front-door | D29: Terceros | E29: 2026-10-22
A30: Azure | B30: Front Door: solicitudes Premium | C30: https://blog.cdnsun.com/microsoft-azure-front-door-pricing/ | D30: Terceros | E30: 2026-10-22
A31: Azure | B31: Blob Hot LRS | C31: https://lucidity.cloud/feeds/blog/azure-storage-cost | D31: Terceros | E31: 2026-10-22
A32: Azure | B32: Blob Archive y recuperación | C32: https://learn.microsoft.com/en-us/answers/questions/866712/billing-question-on-azure-blob-storage | D32: Terceros | E32: 2026-10-22
... A34: Azure | B34: Standard Load Balancer | C34: https://msandbu.org/azure-standard-load-balancer/ | D34: Terceros | E34: 2026-10-22
